Workbook

Sheet Cara Pakai
A1: Referensi Register STM32F405/STM32F407
A2: Contekan untuk bare-metal: alamat, register, pin, dan timer.
A4: Isi workbook
A5: Peta Memori | B5: Flash, SRAM, CCM, area peripheral. Dipakai untuk linker script.
A6: Peripheral | B6: Base address tiap peripheral + register & bit untuk menyalakan clock-nya.
A7: Register | B7: Offset, nilai reset, fungsi, dan bit penting tiap register (RCC, GPIO, TIM, USART, EXTI, SYSCFG, I2C, SPI, FLASH, PWR, SysTick, NVIC, SCB).
A8: Alamat GPIO | B8: Alamat lengkap semua register GPIOA-GPIOI, dihitung otomatis (base + offset).
A9: Alternate Function | B9: Fungsi AF0-AF15 untuk setiap pin PA0-PI11. Pakai filter di kolom Port.
A10: Cari Sinyal | B10: Kebalikan sheet AF: cari nama sinyal (mis. TIM3_CH1, USART2_TX) untuk tahu pin dan nomor AF-nya.
A11: Timer | B11: Ringkasan semua timer: bus, resolusi, channel, clock maks, enable bit, dan pin tiap channel.
A12: Kalkulator Alamat | B12: Ketik nama peripheral + register (sel kuning), alamat lengkap muncul otomatis.
A14: Rumus dasar | B14: Alamat register = Base address peripheral + Offset register
A15: Contoh | B15: Base sebuah GPIO + offset ODR = alamat ODR port itu. Lihat sheet Alamat GPIO.
A17: Sumber | B17: Base address, peta memori, tabel AF, dan data timer: Datasheet DS8626 Rev 12 (Maret 2026), Bab 5 hal. 73-77, Table 9 hal. 64-72, Table 4 hal. 33-34.
B18: Offset register, nilai reset, dan posisi bit: Reference Manual RM0090 dan Cortex-M4 Generic User Guide. Bagian ini disusun dari referensi tersebut, bukan dari PDF yang kamu lampirkan. Cocokkan dulu dengan RM0090 sebelum dipakai di kode.
A19: Catatan paket | B19: Tidak semua pin ada di setiap paket. LQFP64 hanya punya PA, PB, PC, PD2, dan PH0-1. LQFP100 punya PA-PE. PF, PG, PI hanya di paket 144/176 pin. Cek Table 7 datasheet (hal. 49).
A20: Pin yang jangan diganggu | B20: PA13 (SWDIO) dan PA14 (SWCLK) dipakai debugger. Kalau diubah jadi output, ST-Link tidak bisa tersambung lagi tanpa connect-under-reset.

Sheet Peta Memori
A1: Peta Memori STM32F40x
A2: Sumber: DS8626 Figure 18 (hal. 73) dan Bab 3.4-3.6. Ukuran flash tergantung huruf kode chip (E = 512 KB, G = 1 MB).
A4: Area | B4: Alamat awal | C4: Alamat akhir | D4: Ukuran | E4: Isi / fungsi | F4: Dipakai di
A5: Aliased boot area | B5: 0x00000000 | C5: 0x000FFFFF | D5: 1 MB | E5: Cerminan Flash / System memory / SRAM, tergantung pin BOOT | F5: -
A6: Flash (program) | B6: 0x08000000 | C6: 0x080FFFFF | D6: 512 KB atau 1 MB | E6: Kode program & konstanta. Versi 512 KB berakhir di 0x0807FFFF | F6: FLASH di linker script
A7: CCM data RAM | B7: 0x10000000 | C7: 0x1000FFFF | D7: 64 KB | E7: RAM cepat khusus CPU. TIDAK bisa diakses DMA | F7: Opsional (Minggu 7)
A8: System memory + OTP | B8: 0x1FFF0000 | C8: 0x1FFF7A0F | D8: ~30 KB | E8: Bootloader bawaan ST + 512 byte OTP | F8: -
A9: Unique ID (96-bit) | B9: 0x1FFF7A10 | C9: 0x1FFF7A1B | D9: 12 byte | E9: Nomor seri unik chip | F9: -
A10: Flash size register | B10: 0x1FFF7A22 | C10: 0x1FFF7A23 | D10: 2 byte | E10: Ukuran flash dalam KB (bisa dibaca dari kode) | F10: -
A11: Option bytes | B11: 0x1FFFC000 | C11: 0x1FFFC007 | D11: 8 byte | E11: Proteksi baca/tulis, level BOR | F11: -
A12: SRAM1 | B12: 0x20000000 | C12: 0x2001BFFF | D12: 112 KB | E12: RAM utama | F12: RAM di linker script
A13: SRAM2 | B13: 0x2001C000 | C13: 0x2001FFFF | D13: 16 KB | E13: RAM utama (bersambung dengan SRAM1) | F13: RAM di linker script
A14: Peripheral APB1 | B14: 0x40000000 | C14: 0x40007FFF | D14: - | E14: TIM2-7, TIM12-14, USART2/3, UART4/5, I2C, SPI2/3, CAN, PWR, DAC | F14: Sheet Peripheral
A15: Peripheral APB2 | B15: 0x40010000 | C15: 0x40015FFF | D15: - | E15: TIM1/8-11, USART1/6, ADC, SPI1, SDIO, SYSCFG, EXTI | F15: Sheet Peripheral
... A20: Cortex-M4 internal | B20: 0xE0000000 | C20: 0xE00FFFFF | D20: 1 MB | E20: SysTick, NVIC, SCB, debug | F20: Sheet Register
A22: Total SRAM utama | B22: =HEX2DEC(SUBSTITUTE(C13,"0x",""))-HEX2DEC(SUBSTITUTE(B12,"0x",""))+1 -> 131072 | C22: byte
A23: Dalam KB | B23: =B22/1024 -> 128 | C23: KB (SRAM1 + SRAM2, tidak termasuk CCM)

Sheet Peripheral
A1: Base Address Peripheral
A2: Sumber base address: DS8626 Table 10 (hal. 74-77). Register & bit enable clock: RM0090 bab RCC. Filter kolom Bus untuk melihat per bus.
A4: Bus | B4: Peripheral | C4: Base address | D4: Alamat akhir | E4: Kelompok register | F4: Fungsi | G4: Register enable clock | H4: Bit enable
A5: Cortex-M4 | B5: Cortex-M4 internal | C5: 0xE0000000 | D5: 0xE00FFFFF | E5: - | F5: Blok peripheral inti CPU (SysTick, NVIC, SCB, debug). Detail di sheet Register. | G5: - | H5: -
A6: Cortex-M4 | B6: SysTick | C6: 0xE000E010 | D6: 0xE000E01F | E6: SYSTICK | F6: Timer 24-bit bawaan CPU, untuk delay presisi / tick (Minggu 2) | G6: - (selalu aktif) | H6: -
A7: Cortex-M4 | B7: NVIC | C7: 0xE000E100 | D7: 0xE000E4EF | E7: NVIC | F7: Pengendali interrupt: enable/disable IRQ, prioritas | G7: - (selalu aktif) | H7: -
A8: Cortex-M4 | B8: SCB | C8: 0xE000ED00 | D8: 0xE000ED8F | E8: SCB | F8: System Control Block: vector table offset, info fault (HardFault), CPACR untuk FPU | G8: - (selalu aktif) | H8: -
A9: AHB3 | B9: FSMC control | C9: 0xA0000000 | D9: 0xA0000FFF | E9: - | F9: Pengendali memori eksternal (SRAM/NOR/NAND/LCD paralel) | G9: RCC_AHB3ENR | H9: 0 (FSMCEN)
A10: AHB3 | B10: FSMC bank 4 | C10: 0x90000000 | D10: 0x9FFFFFFF | E10: - | F10: Ruang alamat memori eksternal (PC Card) | G10: RCC_AHB3ENR | H10: 0 (FSMCEN)
A11: AHB3 | B11: FSMC bank 3 | C11: 0x80000000 | D11: 0x8FFFFFFF | E11: - | F11: Ruang alamat memori eksternal (NAND) | G11: RCC_AHB3ENR | H11: 0 (FSMCEN)
A12: AHB3 | B12: FSMC bank 2 | C12: 0x70000000 | D12: 0x7FFFFFFF | E12: - | F12: Ruang alamat memori eksternal (NAND) | G12: RCC_AHB3ENR | H12: 0 (FSMCEN)
A13: AHB3 | B13: FSMC bank 1 | C13: 0x60000000 | D13: 0x6FFFFFFF | E13: - | F13: Ruang alamat memori eksternal (NOR/SRAM/LCD) | G13: RCC_AHB3ENR | H13: 0 (FSMCEN)
A14: AHB2 | B14: RNG | C14: 0x50060800 | D14: 0x50060BFF | E14: - | F14: Pembangkit bilangan acak hardware | G14: RCC_AHB2ENR | H14: 6 (RNGEN)
A15: AHB2 | B15: DCMI | C15: 0x50050000 | D15: 0x500503FF | E15: - | F15: Antarmuka kamera paralel | G15: RCC_AHB2ENR | H15: 0 (DCMIEN)
... A72: APB1 | B72: TIM2 | C72: 0x40000000 | D72: 0x400003FF | E72: TIM | F72: General-purpose timer 32-bit, 4 channel | G72: RCC_APB1ENR | H72: 0 (TIM2EN)

Sheet Register
A1: Offset & Bit Register
A2: Alamat register = base peripheral + offset. Sumber: RM0090 (STM32F4) dan ARM Cortex-M4 Generic User Guide. Akses: r = baca, w = tulis, rw = baca-tulis, rc_w0/rc_w1 = hapus dengan menulis 0/1.
A4: Kelompok | B4: Register | C4: Offset | D4: Akses | E4: Nilai reset | F4: Fungsi | G4: Bit penting | H4: Kunci (untuk kalkulator)
A5: RCC | B5: CR | C5: 0x00 | D5: rw | E5: 0x0000XX83 | F5: Nyalakan/cek osilator HSI, HSE, PLL | G5: HSION b0, HSIRDY b1, HSEON b16, HSERDY b17, PLLON b24, PLLRDY b25 | H5: RCC|CR
A6: RCC | B6: PLLCFGR | C6: 0x04 | D6: rw | E6: 0x24003010 | F6: Konfigurasi PLL (M, N, P, Q, sumber) | G6: PLLM b0-5, PLLN b6-14, PLLP b16-17, PLLSRC b22, PLLQ b24-27 | H6: RCC|PLLCFGR
A7: RCC | B7: CFGR | C7: 0x08 | D7: rw | E7: 0x00000000 | F7: Pilih sumber SYSCLK dan pembagi bus AHB/APB1/APB2 | G7: SW b0-1, SWS b2-3, HPRE b4-7, PPRE1 b10-12, PPRE2 b13-15 | H7: RCC|CFGR
A8: RCC | B8: CIR | C8: 0x0C | D8: rw | E8: 0x00000000 | F8: Interrupt dari clock (ready flags) | G8: - | H8: RCC|CIR
A9: RCC | B9: AHB1RSTR | C9: 0x10 | D9: rw | E9: 0x00000000 | F9: Reset peripheral AHB1 (GPIO, DMA, ...) | G9: Posisi bit sama dengan AHB1ENR | H9: RCC|AHB1RSTR
A10: RCC | B10: AHB2RSTR | C10: 0x14 | D10: rw | E10: 0x00000000 | F10: Reset peripheral AHB2 | G10: - | H10: RCC|AHB2RSTR
A11: RCC | B11: AHB3RSTR | C11: 0x18 | D11: rw | E11: 0x00000000 | F11: Reset FSMC | G11: - | H11: RCC|AHB3RSTR
A12: RCC | B12: APB1RSTR | C12: 0x20 | D12: rw | E12: 0x00000000 | F12: Reset peripheral APB1 | G12: Posisi bit sama dengan APB1ENR | H12: RCC|APB1RSTR
A13: RCC | B13: APB2RSTR | C13: 0x24 | D13: rw | E13: 0x00000000 | F13: Reset peripheral APB2 | G13: Posisi bit sama dengan APB2ENR | H13: RCC|APB2RSTR
A14: RCC | B14: AHB1ENR | C14: 0x30 | D14: rw | E14: 0x00100000 | F14: ENABLE CLOCK GPIO, DMA, CRC, dll. Wajib sebelum memakai GPIO! | G14: GPIOAEN b0 ... GPIOIEN b8, CRCEN b12, BKPSRAMEN b18, CCMDATARAMEN b20 (reset = 1), DMA1EN b21, DMA2EN b22 | H14: RCC|AHB1ENR
A15: RCC | B15: AHB2ENR | C15: 0x34 | D15: rw | E15: 0x00000000 | F15: Enable clock DCMI, RNG, USB OTG FS | G15: DCMIEN b0, RNGEN b6, OTGFSEN b7 | H15: RCC|AHB2ENR
... A118: SCB | B118: CPACR | C118: 0x88 | D118: rw | E118: 0x00000000 | F118: Akses FPU (dipakai di startup.c) | G118: CP10 b20-21, CP11 b22-23: isi 11 untuk akses penuh | H118: SCB|CPACR

Sheet Alamat GPIO
A1: Alamat Lengkap Register GPIO
A2: Dihitung otomatis: base port (sheet Peripheral) + offset (sheet Register). Ubah sumbernya, tabel ini ikut berubah.
A4: Port | B4: Base | C4: Enable clock | D4: MODER | E4: OTYPER | F4: OSPEEDR | G4: PUPDR | H4: IDR | I4: ODR | J4: BSRR | K4: LCKR | L4: AFRL | M4: AFRH
A5: GPIOA | B5: =INDEX(Peripheral!$C$5:$C$72,MATCH(A5,Peripheral!$B$5:$B$72,0)) -> 0x40020000 | C5: ="AHB1ENR bit "&LEFT(INDEX(Peripheral!$H$5:$H$72,MATCH(A5,Peripheral!$B$5:$B$72,0)),1) -> AHB1ENR bit 0 | D5: ="0x"&DEC2HEX(HEX2DEC(SUBSTITUTE($B5,"0x",""))+HEX2DEC(SUBSTITUTE(INDEX(Register!$C$5:$C$118,MATCH("GPIO|"&D$4,Register!$H$5:$H$118,0)),"0x","")),8) -> 0x40020000 | E5: ="0x"&DEC2HEX(HEX2DEC(SUBSTITUTE($B5,"0x",""))+HEX2DEC(SUBSTITUTE(INDEX(Register!$C$5:$C$118,MATCH("GPIO|"&E$4,Register!$H$5:$H$118,0)),"0x","")),8) -> 0x40020004 | F5: ="0x"&DEC2HEX(HEX2DEC(SUBSTITUTE($B5,"0x",""))+HEX2DEC(SUBSTITUTE(INDEX(Register!$C$5:$C$118,MATCH("GPIO|"&F$4,Register!$H$5:$H$118,0)),"0x","")),8) -> 0x40020008 | G5: ="0x"&DEC2HEX(HEX2DEC(SUBSTITUTE($B5,"0x",""))+HEX2DEC(SUBSTITUTE(INDEX(Register!$C$5:$C$118,MATCH("GPIO|"&G$4,Register!$H$5:$H$118,0)),"0x","")),8) -> 0x4002000C | H5: ="0x"&DEC2HEX(HEX2DEC(SUBSTITUTE($B5,"0x",""))+HEX2DEC(SUBSTITUTE(INDEX(Register!$C$5:$C$118,MATCH("GPIO|"&H$4,Register!$H$5:$H$118,0)),"0x","")),8) -> 0x40020010 | I5: ="0x"&DEC2HEX(HEX2DEC(SUBSTITUTE($B5,"0x",""))+HEX2DEC(SUBSTITUTE(INDEX(Register!$C$5:$C$118,MATCH("GPIO|"&I$4,Register!$H$5:$H$118,0)),"0x","")),8) -> 0x40020014 | J5: ="0x"&DEC2HEX(HEX2DEC(SUBSTITUTE($B5,"0x",""))+HEX2DEC(SUBSTITUTE(INDEX(Register!$C$5:$C$118,MATCH("GPIO|"&J$4,Register!$H$5:$H$118,0)),"0x","")),8) -> 0x40020018 | K5: ="0x"&DEC2HEX(HEX2DEC(SUBSTITUTE($B5,"0x",""))+HEX2DEC(SUBSTITUTE(INDEX(Register!$C$5:$C$118,MATCH("GPIO|"&K$4,Register!$H$5:$H$118,0)),"0x","")),8) -> 0x4002001C | ... M5: ="0x"&DEC2HEX(HEX2DEC(SUBSTITUTE($B5,"0x",""))+HEX2DEC(SUBSTITUTE(INDEX(Register!$C$5:$C$118,MATCH("GPIO|"&M$4,Register!$H$5:$H$118,0)),"0x","")),8) -> 0x40020024
A6: GPIOB | B6: =INDEX(Peripheral!$C$5:$C$72,MATCH(A6,Peripheral!$B$5:$B$72,0)) -> 0x40020400 | C6: ="AHB1ENR bit "&LEFT(INDEX(Peripheral!$H$5:$H$72,MATCH(A6,Peripheral!$B$5:$B$72,0)),1) -> AHB1ENR bit 1 | D6: ="0x"&DEC2HEX(HEX2DEC(SUBSTITUTE($B6,"0x",""))+HEX2DEC(SUBSTITUTE(INDEX(Register!$C$5:$C$118,MATCH("GPIO|"&D$4,Register!$H$5:$H$118,0)),"0x","")),8) -> 0x40020400 | E6: ="0x"&DEC2HEX(HEX2DEC(SUBSTITUTE($B6,"0x",""))+HEX2DEC(SUBSTITUTE(INDEX(Register!$C$5:$C$118,MATCH("GPIO|"&E$4,Register!$H$5:$H$118,0)),"0x","")),8) -> 0x40020404 | F6: ="0x"&DEC2HEX(HEX2DEC(SUBSTITUTE($B6,"0x",""))+HEX2DEC(SUBSTITUTE(INDEX(Register!$C$5:$C$118,MATCH("GPIO|"&F$4,Register!$H$5:$H$118,0)),"0x","")),8) -> 0x40020408 | G6: ="0x"&DEC2HEX(HEX2DEC(SUBSTITUTE($B6,"0x",""))+HEX2DEC(SUBSTITUTE(INDEX(Register!$C$5:$C$118,MATCH("GPIO|"&G$4,Register!$H$5:$H$118,0)),"0x","")),8) -> 0x4002040C | H6: ="0x"&DEC2HEX(HEX2DEC(SUBSTITUTE($B6,"0x",""))+HEX2DEC(SUBSTITUTE(INDEX(Register!$C$5:$C$118,MATCH("GPIO|"&H$4,Register!$H$5:$H$118,0)),"0x","")),8) -> 0x40020410 | I6: ="0x"&DEC2HEX(HEX2DEC(SUBSTITUTE($B6,"0x",""))+HEX2DEC(SUBSTITUTE(INDEX(Register!$C$5:$C$118,MATCH("GPIO|"&I$4,Register!$H$5:$H$118,0)),"0x","")),8) -> 0x40020414 | J6: ="0x"&DEC2HEX(HEX2DEC(SUBSTITUTE($B6,"0x",""))+HEX2DEC(SUBSTITUTE(INDEX(Register!$C$5:$C$118,MATCH("GPIO|"&J$4,Register!$H$5:$H$118,0)),"0x","")),8) -> 0x40020418 | K6: ="0x"&DEC2HEX(HEX2DEC(SUBSTITUTE($B6,"0x",""))+HEX2DEC(SUBSTITUTE(INDEX(Register!$C$5:$C$118,MATCH("GPIO|"&K$4,Register!$H$5:$H$118,0)),"0x","")),8) -> 0x4002041C | ... M6: ="0x"&DEC2HEX(HEX2DEC(SUBSTITUTE($B6,"0x",""))+HEX2DEC(SUBSTITUTE(INDEX(Register!$C$5:$C$118,MATCH("GPIO|"&M$4,Register!$H$5:$H$118,0)),"0x","")),8) -> 0x40020424
A7: GPIOC | B7: =INDEX(Peripheral!$C$5:$C$72,MATCH(A7,Peripheral!$B$5:$B$72,0)) -> 0x40020800 | C7: ="AHB1ENR bit "&LEFT(INDEX(Peripheral!$H$5:$H$72,MATCH(A7,Peripheral!$B$5:$B$72,0)),1) -> AHB1ENR bit 2 | D7: ="0x"&DEC2HEX(HEX2DEC(SUBSTITUTE($B7,"0x",""))+HEX2DEC(SUBSTITUTE(INDEX(Register!$C$5:$C$118,MATCH("GPIO|"&D$4,Register!$H$5:$H$118,0)),"0x","")),8) -> 0x40020800 | E7: ="0x"&DEC2HEX(HEX2DEC(SUBSTITUTE($B7,"0x",""))+HEX2DEC(SUBSTITUTE(INDEX(Register!$C$5:$C$118,MATCH("GPIO|"&E$4,Register!$H$5:$H$118,0)),"0x","")),8) -> 0x40020804 | F7: ="0x"&DEC2HEX(HEX2DEC(SUBSTITUTE($B7,"0x",""))+HEX2DEC(SUBSTITUTE(INDEX(Register!$C$5:$C$118,MATCH("GPIO|"&F$4,Register!$H$5:$H$118,0)),"0x","")),8) -> 0x40020808 | G7: ="0x"&DEC2HEX(HEX2DEC(SUBSTITUTE($B7,"0x",""))+HEX2DEC(SUBSTITUTE(INDEX(Register!$C$5:$C$118,MATCH("GPIO|"&G$4,Register!$H$5:$H$118,0)),"0x","")),8) -> 0x4002080C | H7: ="0x"&DEC2HEX(HEX2DEC(SUBSTITUTE($B7,"0x",""))+HEX2DEC(SUBSTITUTE(INDEX(Register!$C$5:$C$118,MATCH("GPIO|"&H$4,Register!$H$5:$H$118,0)),"0x","")),8) -> 0x40020810 | I7: ="0x"&DEC2HEX(HEX2DEC(SUBSTITUTE($B7,"0x",""))+HEX2DEC(SUBSTITUTE(INDEX(Register!$C$5:$C$118,MATCH("GPIO|"&I$4,Register!$H$5:$H$118,0)),"0x","")),8) -> 0x40020814 | J7: ="0x"&DEC2HEX(HEX2DEC(SUBSTITUTE($B7,"0x",""))+HEX2DEC(SUBSTITUTE(INDEX(Register!$C$5:$C$118,MATCH("GPIO|"&J$4,Register!$H$5:$H$118,0)),"0x","")),8) -> 0x40020818 | K7: ="0x"&DEC2HEX(HEX2DEC(SUBSTITUTE($B7,"0x",""))+HEX2DEC(SUBSTITUTE(INDEX(Register!$C$5:$C$118,MATCH("GPIO|"&K$4,Register!$H$5:$H$118,0)),"0x","")),8) -> 0x4002081C | ... M7: ="0x"&DEC2HEX(HEX2DEC(SUBSTITUTE($B7,"0x",""))+HEX2DEC(SUBSTITUTE(INDEX(Register!$C$5:$C$118,MATCH("GPIO|"&M$4,Register!$H$5:$H$118,0)),"0x","")),8) -> 0x40020824
A8: GPIOD | B8: =INDEX(Peripheral!$C$5:$C$72,MATCH(A8,Peripheral!$B$5:$B$72,0)) -> 0x40020C00 | C8: ="AHB1ENR bit "&LEFT(INDEX(Peripheral!$H$5:$H$72,MATCH(A8,Peripheral!$B$5:$B$72,0)),1) -> AHB1ENR bit 3 | D8: ="0x"&DEC2HEX(HEX2DEC(SUBSTITUTE($B8,"0x",""))+HEX2DEC(SUBSTITUTE(INDEX(Register!$C$5:$C$118,MATCH("GPIO|"&D$4,Register!$H$5:$H$118,0)),"0x","")),8) -> 0x40020C00 | E8: ="0x"&DEC2HEX(HEX2DEC(SUBSTITUTE($B8,"0x",""))+HEX2DEC(SUBSTITUTE(INDEX(Register!$C$5:$C$118,MATCH("GPIO|"&E$4,Register!$H$5:$H$118,0)),"0x","")),8) -> 0x40020C04 | F8: ="0x"&DEC2HEX(HEX2DEC(SUBSTITUTE($B8,"0x",""))+HEX2DEC(SUBSTITUTE(INDEX(Register!$C$5:$C$118,MATCH("GPIO|"&F$4,Register!$H$5:$H$118,0)),"0x","")),8) -> 0x40020C08 | G8: ="0x"&DEC2HEX(HEX2DEC(SUBSTITUTE($B8,"0x",""))+HEX2DEC(SUBSTITUTE(INDEX(Register!$C$5:$C$118,MATCH("GPIO|"&G$4,Register!$H$5:$H$118,0)),"0x","")),8) -> 0x40020C0C | H8: ="0x"&DEC2HEX(HEX2DEC(SUBSTITUTE($B8,"0x",""))+HEX2DEC(SUBSTITUTE(INDEX(Register!$C$5:$C$118,MATCH("GPIO|"&H$4,Register!$H$5:$H$118,0)),"0x","")),8) -> 0x40020C10 | I8: ="0x"&DEC2HEX(HEX2DEC(SUBSTITUTE($B8,"0x",""))+HEX2DEC(SUBSTITUTE(INDEX(Register!$C$5:$C$118,MATCH("GPIO|"&I$4,Register!$H$5:$H$118,0)),"0x","")),8) -> 0x40020C14 | J8: ="0x"&DEC2HEX(HEX2DEC(SUBSTITUTE($B8,"0x",""))+HEX2DEC(SUBSTITUTE(INDEX(Register!$C$5:$C$118,MATCH("GPIO|"&J$4,Register!$H$5:$H$118,0)),"0x","")),8) -> 0x40020C18 | K8: ="0x"&DEC2HEX(HEX2DEC(SUBSTITUTE($B8,"0x",""))+HEX2DEC(SUBSTITUTE(INDEX(Register!$C$5:$C$118,MATCH("GPIO|"&K$4,Register!$H$5:$H$118,0)),"0x","")),8) -> 0x40020C1C | ... M8: ="0x"&DEC2HEX(HEX2DEC(SUBSTITUTE($B8,"0x",""))+HEX2DEC(SUBSTITUTE(INDEX(Register!$C$5:$C$118,MATCH("GPIO|"&M$4,Register!$H$5:$H$118,0)),"0x","")),8) -> 0x40020C24
A9: GPIOE | B9: =INDEX(Peripheral!$C$5:$C$72,MATCH(A9,Peripheral!$B$5:$B$72,0)) -> 0x40021000 | C9: ="AHB1ENR bit "&LEFT(INDEX(Peripheral!$H$5:$H$72,MATCH(A9,Peripheral!$B$5:$B$72,0)),1) -> AHB1ENR bit 4 | D9: ="0x"&DEC2HEX(HEX2DEC(SUBSTITUTE($B9,"0x",""))+HEX2DEC(SUBSTITUTE(INDEX(Register!$C$5:$C$118,MATCH("GPIO|"&D$4,Register!$H$5:$H$118,0)),"0x","")),8) -> 0x40021000 | E9: ="0x"&DEC2HEX(HEX2DEC(SUBSTITUTE($B9,"0x",""))+HEX2DEC(SUBSTITUTE(INDEX(Register!$C$5:$C$118,MATCH("GPIO|"&E$4,Register!$H$5:$H$118,0)),"0x","")),8) -> 0x40021004 | F9: ="0x"&DEC2HEX(HEX2DEC(SUBSTITUTE($B9,"0x",""))+HEX2DEC(SUBSTITUTE(INDEX(Register!$C$5:$C$118,MATCH("GPIO|"&F$4,Register!$H$5:$H$118,0)),"0x","")),8) -> 0x40021008 | G9: ="0x"&DEC2HEX(HEX2DEC(SUBSTITUTE($B9,"0x",""))+HEX2DEC(SUBSTITUTE(INDEX(Register!$C$5:$C$118,MATCH("GPIO|"&G$4,Register!$H$5:$H$118,0)),"0x","")),8) -> 0x4002100C | H9: ="0x"&DEC2HEX(HEX2DEC(SUBSTITUTE($B9,"0x",""))+HEX2DEC(SUBSTITUTE(INDEX(Register!$C$5:$C$118,MATCH("GPIO|"&H$4,Register!$H$5:$H$118,0)),"0x","")),8) -> 0x40021010 | I9: ="0x"&DEC2HEX(HEX2DEC(SUBSTITUTE($B9,"0x",""))+HEX2DEC(SUBSTITUTE(INDEX(Register!$C$5:$C$118,MATCH("GPIO|"&I$4,Register!$H$5:$H$118,0)),"0x","")),8) -> 0x40021014 | J9: ="0x"&DEC2HEX(HEX2DEC(SUBSTITUTE($B9,"0x",""))+HEX2DEC(SUBSTITUTE(INDEX(Register!$C$5:$C$118,MATCH("GPIO|"&J$4,Register!$H$5:$H$118,0)),"0x","")),8) -> 0x40021018 | K9: ="0x"&DEC2HEX(HEX2DEC(SUBSTITUTE($B9,"0x",""))+HEX2DEC(SUBSTITUTE(INDEX(Register!$C$5:$C$118,MATCH("GPIO|"&K$4,Register!$H$5:$H$118,0)),"0x","")),8) -> 0x4002101C | ... M9: ="0x"&DEC2HEX(HEX2DEC(SUBSTITUTE($B9,"0x",""))+HEX2DEC(SUBSTITUTE(INDEX(Register!$C$5:$C$118,MATCH("GPIO|"&M$4,Register!$H$5:$H$118,0)),"0x","")),8) -> 0x40021024
A10: GPIOF | B10: =INDEX(Peripheral!$C$5:$C$72,MATCH(A10,Peripheral!$B$5:$B$72,0)) -> 0x40021400 | C10: ="AHB1ENR bit "&LEFT(INDEX(Peripheral!$H$5:$H$72,MATCH(A10,Peripheral!$B$5:$B$72,0)),1) -> AHB1ENR bit 5 | D10: ="0x"&DEC2HEX(HEX2DEC(SUBSTITUTE($B10,"0x",""))+HEX2DEC(SUBSTITUTE(INDEX(Register!$C$5:$C$118,MATCH("GPIO|"&D$4,Register!$H$5:$H$118,0)),"0x","")),8) -> 0x40021400 | E10: ="0x"&DEC2HEX(HEX2DEC(SUBSTITUTE($B10,"0x",""))+HEX2DEC(SUBSTITUTE(INDEX(Register!$C$5:$C$118,MATCH("GPIO|"&E$4,Register!$H$5:$H$118,0)),"0x","")),8) -> 0x40021404 | F10: ="0x"&DEC2HEX(HEX2DEC(SUBSTITUTE($B10,"0x",""))+HEX2DEC(SUBSTITUTE(INDEX(Register!$C$5:$C$118,MATCH("GPIO|"&F$4,Register!$H$5:$H$118,0)),"0x","")),8) -> 0x40021408 | G10: ="0x"&DEC2HEX(HEX2DEC(SUBSTITUTE($B10,"0x",""))+HEX2DEC(SUBSTITUTE(INDEX(Register!$C$5:$C$118,MATCH("GPIO|"&G$4,Register!$H$5:$H$118,0)),"0x","")),8) -> 0x4002140C | H10: ="0x"&DEC2HEX(HEX2DEC(SUBSTITUTE($B10,"0x",""))+HEX2DEC(SUBSTITUTE(INDEX(Register!$C$5:$C$118,MATCH("GPIO|"&H$4,Register!$H$5:$H$118,0)),"0x","")),8) -> 0x40021410 | I10: ="0x"&DEC2HEX(HEX2DEC(SUBSTITUTE($B10,"0x",""))+HEX2DEC(SUBSTITUTE(INDEX(Register!$C$5:$C$118,MATCH("GPIO|"&I$4,Register!$H$5:$H$118,0)),"0x","")),8) -> 0x40021414 | J10: ="0x"&DEC2HEX(HEX2DEC(SUBSTITUTE($B10,"0x",""))+HEX2DEC(SUBSTITUTE(INDEX(Register!$C$5:$C$118,MATCH("GPIO|"&J$4,Register!$H$5:$H$118,0)),"0x","")),8) -> 0x40021418 | K10: ="0x"&DEC2HEX(HEX2DEC(SUBSTITUTE($B10,"0x",""))+HEX2DEC(SUBSTITUTE(INDEX(Register!$C$5:$C$118,MATCH("GPIO|"&K$4,Register!$H$5:$H$118,0)),"0x","")),8) -> 0x4002141C | ... M10: ="0x"&DEC2HEX(HEX2DEC(SUBSTITUTE($B10,"0x",""))+HEX2DEC(SUBSTITUTE(INDEX(Register!$C$5:$C$118,MATCH("GPIO|"&M$4,Register!$H$5:$H$118,0)),"0x","")),8) -> 0x40021424
A11: GPIOG | B11: =INDEX(Peripheral!$C$5:$C$72,MATCH(A11,Peripheral!$B$5:$B$72,0)) -> 0x40021800 | C11: ="AHB1ENR bit "&LEFT(INDEX(Peripheral!$H$5:$H$72,MATCH(A11,Peripheral!$B$5:$B$72,0)),1) -> AHB1ENR bit 6 | D11: ="0x"&DEC2HEX(HEX2DEC(SUBSTITUTE($B11,"0x",""))+HEX2DEC(SUBSTITUTE(INDEX(Register!$C$5:$C$118,MATCH("GPIO|"&D$4,Register!$H$5:$H$118,0)),"0x","")),8) -> 0x40021800 | E11: ="0x"&DEC2HEX(HEX2DEC(SUBSTITUTE($B11,"0x",""))+HEX2DEC(SUBSTITUTE(INDEX(Register!$C$5:$C$118,MATCH("GPIO|"&E$4,Register!$H$5:$H$118,0)),"0x","")),8) -> 0x40021804 | F11: ="0x"&DEC2HEX(HEX2DEC(SUBSTITUTE($B11,"0x",""))+HEX2DEC(SUBSTITUTE(INDEX(Register!$C$5:$C$118,MATCH("GPIO|"&F$4,Register!$H$5:$H$118,0)),"0x","")),8) -> 0x40021808 | G11: ="0x"&DEC2HEX(HEX2DEC(SUBSTITUTE($B11,"0x",""))+HEX2DEC(SUBSTITUTE(INDEX(Register!$C$5:$C$118,MATCH("GPIO|"&G$4,Register!$H$5:$H$118,0)),"0x","")),8) -> 0x4002180C | H11: ="0x"&DEC2HEX(HEX2DEC(SUBSTITUTE($B11,"0x",""))+HEX2DEC(SUBSTITUTE(INDEX(Register!$C$5:$C$118,MATCH("GPIO|"&H$4,Register!$H$5:$H$118,0)),"0x","")),8) -> 0x40021810 | I11: ="0x"&DEC2HEX(HEX2DEC(SUBSTITUTE($B11,"0x",""))+HEX2DEC(SUBSTITUTE(INDEX(Register!$C$5:$C$118,MATCH("GPIO|"&I$4,Register!$H$5:$H$118,0)),"0x","")),8) -> 0x40021814 | J11: ="0x"&DEC2HEX(HEX2DEC(SUBSTITUTE($B11,"0x",""))+HEX2DEC(SUBSTITUTE(INDEX(Register!$C$5:$C$118,MATCH("GPIO|"&J$4,Register!$H$5:$H$118,0)),"0x","")),8) -> 0x40021818 | K11: ="0x"&DEC2HEX(HEX2DEC(SUBSTITUTE($B11,"0x",""))+HEX2DEC(SUBSTITUTE(INDEX(Register!$C$5:$C$118,MATCH("GPIO|"&K$4,Register!$H$5:$H$118,0)),"0x","")),8) -> 0x4002181C | ... M11: ="0x"&DEC2HEX(HEX2DEC(SUBSTITUTE($B11,"0x",""))+HEX2DEC(SUBSTITUTE(INDEX(Register!$C$5:$C$118,MATCH("GPIO|"&M$4,Register!$H$5:$H$118,0)),"0x","")),8) -> 0x40021824
A12: GPIOH | B12: =INDEX(Peripheral!$C$5:$C$72,MATCH(A12,Peripheral!$B$5:$B$72,0)) -> 0x40021C00 | C12: ="AHB1ENR bit "&LEFT(INDEX(Peripheral!$H$5:$H$72,MATCH(A12,Peripheral!$B$5:$B$72,0)),1) -> AHB1ENR bit 7 | D12: ="0x"&DEC2HEX(HEX2DEC(SUBSTITUTE($B12,"0x",""))+HEX2DEC(SUBSTITUTE(INDEX(Register!$C$5:$C$118,MATCH("GPIO|"&D$4,Register!$H$5:$H$118,0)),"0x","")),8) -> 0x40021C00 | E12: ="0x"&DEC2HEX(HEX2DEC(SUBSTITUTE($B12,"0x",""))+HEX2DEC(SUBSTITUTE(INDEX(Register!$C$5:$C$118,MATCH("GPIO|"&E$4,Register!$H$5:$H$118,0)),"0x","")),8) -> 0x40021C04 | F12: ="0x"&DEC2HEX(HEX2DEC(SUBSTITUTE($B12,"0x",""))+HEX2DEC(SUBSTITUTE(INDEX(Register!$C$5:$C$118,MATCH("GPIO|"&F$4,Register!$H$5:$H$118,0)),"0x","")),8) -> 0x40021C08 | G12: ="0x"&DEC2HEX(HEX2DEC(SUBSTITUTE($B12,"0x",""))+HEX2DEC(SUBSTITUTE(INDEX(Register!$C$5:$C$118,MATCH("GPIO|"&G$4,Register!$H$5:$H$118,0)),"0x","")),8) -> 0x40021C0C | H12: ="0x"&DEC2HEX(HEX2DEC(SUBSTITUTE($B12,"0x",""))+HEX2DEC(SUBSTITUTE(INDEX(Register!$C$5:$C$118,MATCH("GPIO|"&H$4,Register!$H$5:$H$118,0)),"0x","")),8) -> 0x40021C10 | I12: ="0x"&DEC2HEX(HEX2DEC(SUBSTITUTE($B12,"0x",""))+HEX2DEC(SUBSTITUTE(INDEX(Register!$C$5:$C$118,MATCH("GPIO|"&I$4,Register!$H$5:$H$118,0)),"0x","")),8) -> 0x40021C14 | J12: ="0x"&DEC2HEX(HEX2DEC(SUBSTITUTE($B12,"0x",""))+HEX2DEC(SUBSTITUTE(INDEX(Register!$C$5:$C$118,MATCH("GPIO|"&J$4,Register!$H$5:$H$118,0)),"0x","")),8) -> 0x40021C18 | K12: ="0x"&DEC2HEX(HEX2DEC(SUBSTITUTE($B12,"0x",""))+HEX2DEC(SUBSTITUTE(INDEX(Register!$C$5:$C$118,MATCH("GPIO|"&K$4,Register!$H$5:$H$118,0)),"0x","")),8) -> 0x40021C1C | ... M12: ="0x"&DEC2HEX(HEX2DEC(SUBSTITUTE($B12,"0x",""))+HEX2DEC(SUBSTITUTE(INDEX(Register!$C$5:$C$118,MATCH("GPIO|"&M$4,Register!$H$5:$H$118,0)),"0x","")),8) -> 0x40021C24
A13: GPIOI | B13: =INDEX(Peripheral!$C$5:$C$72,MATCH(A13,Peripheral!$B$5:$B$72,0)) -> 0x40022000 | C13: ="AHB1ENR bit "&LEFT(INDEX(Peripheral!$H$5:$H$72,MATCH(A13,Peripheral!$B$5:$B$72,0)),1) -> AHB1ENR bit 8 | D13: ="0x"&DEC2HEX(HEX2DEC(SUBSTITUTE($B13,"0x",""))+HEX2DEC(SUBSTITUTE(INDEX(Register!$C$5:$C$118,MATCH("GPIO|"&D$4,Register!$H$5:$H$118,0)),"0x","")),8) -> 0x40022000 | E13: ="0x"&DEC2HEX(HEX2DEC(SUBSTITUTE($B13,"0x",""))+HEX2DEC(SUBSTITUTE(INDEX(Register!$C$5:$C$118,MATCH("GPIO|"&E$4,Register!$H$5:$H$118,0)),"0x","")),8) -> 0x40022004 | F13: ="0x"&DEC2HEX(HEX2DEC(SUBSTITUTE($B13,"0x",""))+HEX2DEC(SUBSTITUTE(INDEX(Register!$C$5:$C$118,MATCH("GPIO|"&F$4,Register!$H$5:$H$118,0)),"0x","")),8) -> 0x40022008 | G13: ="0x"&DEC2HEX(HEX2DEC(SUBSTITUTE($B13,"0x",""))+HEX2DEC(SUBSTITUTE(INDEX(Register!$C$5:$C$118,MATCH("GPIO|"&G$4,Register!$H$5:$H$118,0)),"0x","")),8) -> 0x4002200C | H13: ="0x"&DEC2HEX(HEX2DEC(SUBSTITUTE($B13,"0x",""))+HEX2DEC(SUBSTITUTE(INDEX(Register!$C$5:$C$118,MATCH("GPIO|"&H$4,Register!$H$5:$H$118,0)),"0x","")),8) -> 0x40022010 | I13: ="0x"&DEC2HEX(HEX2DEC(SUBSTITUTE($B13,"0x",""))+HEX2DEC(SUBSTITUTE(INDEX(Register!$C$5:$C$118,MATCH("GPIO|"&I$4,Register!$H$5:$H$118,0)),"0x","")),8) -> 0x40022014 | J13: ="0x"&DEC2HEX(HEX2DEC(SUBSTITUTE($B13,"0x",""))+HEX2DEC(SUBSTITUTE(INDEX(Register!$C$5:$C$118,MATCH("GPIO|"&J$4,Register!$H$5:$H$118,0)),"0x","")),8) -> 0x40022018 | K13: ="0x"&DEC2HEX(HEX2DEC(SUBSTITUTE($B13,"0x",""))+HEX2DEC(SUBSTITUTE(INDEX(Register!$C$5:$C$118,MATCH("GPIO|"&K$4,Register!$H$5:$H$118,0)),"0x","")),8) -> 0x4002201C | ... M13: ="0x"&DEC2HEX(HEX2DEC(SUBSTITUTE($B13,"0x",""))+HEX2DEC(SUBSTITUTE(INDEX(Register!$C$5:$C$118,MATCH("GPIO|"&M$4,Register!$H$5:$H$118,0)),"0x","")),8) -> 0x40022024
A15: Contoh pemakaian di kode: #define GPIOx_ODR (*(volatile uint32_t *)0x........) ← isi dengan alamat dari kolom ODR port-mu.
A17: Alamat register RCC penting
A18: Register | B18: Alamat
A19: RCC_CR | B19: ="0x"&DEC2HEX(HEX2DEC(SUBSTITUTE(INDEX(Peripheral!$C$5:$C$72,MATCH("RCC",Peripheral!$B$5:$B$72,0)),"0x",""))+HEX2DEC(SUBSTITUTE(INDEX(Register!$C$5:$C$118,MATCH("RCC|CR",Register!$H$5:$H$118,0)),"0x","")),8) -> 0x40023800
A20: RCC_PLLCFGR | B20: ="0x"&DEC2HEX(HEX2DEC(SUBSTITUTE(INDEX(Peripheral!$C$5:$C$72,MATCH("RCC",Peripheral!$B$5:$B$72,0)),"0x",""))+HEX2DEC(SUBSTITUTE(INDEX(Register!$C$5:$C$118,MATCH("RCC|PLLCFGR",Register!$H$5:$H$118,0)),"0x","")),8) -> 0x40023804
A21: RCC_CFGR | B21: ="0x"&DEC2HEX(HEX2DEC(SUBSTITUTE(INDEX(Peripheral!$C$5:$C$72,MATCH("RCC",Peripheral!$B$5:$B$72,0)),"0x",""))+HEX2DEC(SUBSTITUTE(INDEX(Register!$C$5:$C$118,MATCH("RCC|CFGR",Register!$H$5:$H$118,0)),"0x","")),8) -> 0x40023808
A22: RCC_AHB1ENR | B22: ="0x"&DEC2HEX(HEX2DEC(SUBSTITUTE(INDEX(Peripheral!$C$5:$C$72,MATCH("RCC",Peripheral!$B$5:$B$72,0)),"0x",""))+HEX2DEC(SUBSTITUTE(INDEX(Register!$C$5:$C$118,MATCH("RCC|AHB1ENR",Register!$H$5:$H$118,0)),"0x","")),8) -> 0x40023830
A23: RCC_AHB2ENR | B23: ="0x"&DEC2HEX(HEX2DEC(SUBSTITUTE(INDEX(Peripheral!$C$5:$C$72,MATCH("RCC",Peripheral!$B$5:$B$72,0)),"0x",""))+HEX2DEC(SUBSTITUTE(INDEX(Register!$C$5:$C$118,MATCH("RCC|AHB2ENR",Register!$H$5:$H$118,0)),"0x","")),8) -> 0x40023834
A24: RCC_APB1ENR | B24: ="0x"&DEC2HEX(HEX2DEC(SUBSTITUTE(INDEX(Peripheral!$C$5:$C$72,MATCH("RCC",Peripheral!$B$5:$B$72,0)),"0x",""))+HEX2DEC(SUBSTITUTE(INDEX(Register!$C$5:$C$118,MATCH("RCC|APB1ENR",Register!$H$5:$H$118,0)),"0x","")),8) -> 0x40023840
A25: RCC_APB2ENR | B25: ="0x"&DEC2HEX(HEX2DEC(SUBSTITUTE(INDEX(Peripheral!$C$5:$C$72,MATCH("RCC",Peripheral!$B$5:$B$72,0)),"0x",""))+HEX2DEC(SUBSTITUTE(INDEX(Register!$C$5:$C$118,MATCH("RCC|APB2ENR",Register!$H$5:$H$118,0)),"0x","")),8) -> 0x40023844
A26: RCC_BDCR | B26: ="0x"&DEC2HEX(HEX2DEC(SUBSTITUTE(INDEX(Peripheral!$C$5:$C$72,MATCH("RCC",Peripheral!$B$5:$B$72,0)),"0x",""))+HEX2DEC(SUBSTITUTE(INDEX(Register!$C$5:$C$118,MATCH("RCC|BDCR",Register!$H$5:$H$118,0)),"0x","")),8) -> 0x40023870
A27: RCC_CSR | B27: ="0x"&DEC2HEX(HEX2DEC(SUBSTITUTE(INDEX(Peripheral!$C$5:$C$72,MATCH("RCC",Peripheral!$B$5:$B$72,0)),"0x",""))+HEX2DEC(SUBSTITUTE(INDEX(Register!$C$5:$C$118,MATCH("RCC|CSR",Register!$H$5:$H$118,0)),"0x","")),8) -> 0x40023874

Sheet Alternate Function
A1: Alternate Function Mapping (AF0-AF15)
A2: Sumber: DS8626 Table 9 (hal. 64-72). Nilai AF ditulis ke GPIOx_AFRL (pin 0-7) atau AFRH (pin 8-15), dan MODER pin harus 10 (alternate function).
A4: Port | B4: Pin | C4: AF0 | D4: AF1 | E4: AF2 | F4: AF3 | G4: AF4 | H4: AF5 | I4: AF6 | J4: AF7 | K4: AF8 | L4: AF9 | M4: AF10 | N4: AF11 | O4: AF12 | P4: AF13 | Q4: AF14 | R4: AF15 | S4: Catatan
B5: Grup → | C5: SYS | D5: TIM1/2 | E5: TIM3/4/5 | F5: TIM8/9/10/11 | G5: I2C1/2/3 | H5: SPI1/SPI2/I2S2/I2S2ext | I5: SPI3/I2Sext/I2S3 | J5: USART1/2/3/I2S3ext | K5: UART4/5/USART6 | L5: CAN1/2/TIM12/13/14 | M5: OTG_FS/OTG_HS | N5: ETH | O5: FSMC/SDIO/OTG_FS | P5: DCMI | Q5: - | R5: -
A6: Port A | B6: PA0 | C6: - | D6: TIM2_CH1_ETR | E6: TIM5_CH1 | F6: TIM8_ETR | G6: - | H6: - | I6: - | J6: USART2_CTS | K6: UART4_TX | L6: - | M6: - | N6: ETH_MII_CRS | O6: - | P6: - | Q6: - | R6: EVENTOUT | S6: Juga WKUP (bangun dari Standby)
A7: Port A | B7: PA1 | C7: - | D7: TIM2_CH2 | E7: TIM5_CH2 | F7: - | G7: - | H7: - | I7: - | J7: USART2_RTS | K7: UART4_RX | L7: - | M7: - | N7: ETH_MII_RX_CLK / ETH_RMII_REF_CLK | O7: - | P7: - | Q7: - | R7: EVENTOUT
A8: Port A | B8: PA2 | C8: - | D8: TIM2_CH3 | E8: TIM5_CH3 | F8: TIM9_CH1 | G8: - | H8: - | I8: - | J8: USART2_TX | K8: - | L8: - | M8: - | N8: ETH_MDIO | O8: - | P8: - | Q8: - | R8: EVENTOUT
A9: Port A | B9: PA3 | C9: - | D9: TIM2_CH4 | E9: TIM5_CH4 | F9: TIM9_CH2 | G9: - | H9: - | I9: - | J9: USART2_RX | K9: - | L9: - | M9: OTG_HS_ULPI_D0 | N9: ETH_MII_COL | O9: - | P9: - | Q9: - | R9: EVENTOUT
A10: Port A | B10: PA4 | C10: - | D10: - | E10: - | F10: - | G10: - | H10: SPI1_NSS | I10: SPI3_NSS / I2S3_WS | J10: USART2_CK | K10: - | L10: - | M10: - | N10: - | O10: OTG_HS_SOF | P10: DCMI_HSYNC | Q10: - | R10: EVENTOUT
A11: Port A | B11: PA5 | C11: - | D11: TIM2_CH1_ETR | E11: - | F11: TIM8_CH1N | G11: - | H11: SPI1_SCK | I11: - | J11: - | K11: - | L11: - | M11: OTG_HS_ULPI_CK | N11: - | O11: - | P11: - | Q11: - | R11: EVENTOUT
A12: Port A | B12: PA6 | C12: - | D12: TIM1_BKIN | E12: TIM3_CH1 | F12: TIM8_BKIN | G12: - | H12: SPI1_MISO | I12: - | J12: - | K12: - | L12: TIM13_CH1 | M12: - | N12: - | O12: - | P12: DCMI_PIXCLK | Q12: - | R12: EVENTOUT
A13: Port A | B13: PA7 | C13: - | D13: TIM1_CH1N | E13: TIM3_CH2 | F13: TIM8_CH1N | G13: - | H13: SPI1_MOSI | I13: - | J13: - | K13: - | L13: TIM14_CH1 | M13: - | N13: ETH_MII_RX_DV / ETH_RMII_CRS_DV | O13: - | P13: - | Q13: - | R13: EVENTOUT
A14: Port A | B14: PA8 | C14: MCO1 | D14: TIM1_CH1 | E14: - | F14: - | G14: I2C3_SCL | H14: - | I14: - | J14: USART1_CK | K14: - | L14: - | M14: OTG_FS_SOF | N14: - | O14: - | P14: - | Q14: - | R14: EVENTOUT
A15: Port A | B15: PA9 | C15: - | D15: TIM1_CH2 | E15: - | F15: - | G15: I2C3_SMBA | H15: - | I15: - | J15: USART1_TX | K15: - | L15: - | M15: - | N15: - | O15: - | P15: DCMI_D0 | Q15: - | R15: EVENTOUT
A16: Port A | B16: PA10 | C16: - | D16: TIM1_CH3 | E16: - | F16: - | G16: - | H16: - | I16: - | J16: USART1_RX | K16: - | L16: - | M16: OTG_FS_ID | N16: - | O16: - | P16: DCMI_D1 | Q16: - | R16: EVENTOUT
A17: Port A | B17: PA11 | C17: - | D17: TIM1_CH4 | E17: - | F17: - | G17: - | H17: - | I17: - | J17: USART1_CTS | K17: - | L17: CAN1_RX | M17: OTG_FS_DM | N17: - | O17: - | P17: - | Q17: - | R17: EVENTOUT
A18: Port A | B18: PA12 | C18: - | D18: TIM1_ETR | E18: - | F18: - | G18: - | H18: - | I18: - | J18: USART1_RTS | K18: - | L18: CAN1_TX | M18: OTG_FS_DP | N18: - | O18: - | P18: - | Q18: - | R18: EVENTOUT
A19: Port A | B19: PA13 | C19: JTMS-SWDIO | D19: - | E19: - | F19: - | G19: - | H19: - | I19: - | J19: - | K19: - | L19: - | M19: - | N19: - | O19: - | P19: - | Q19: - | R19: EVENTOUT | S19: SWDIO debugger, jangan diubah
A20: Port A | B20: PA14 | C20: JTCK-SWCLK | D20: - | E20: - | F20: - | G20: - | H20: - | I20: - | J20: - | K20: - | L20: - | M20: - | N20: - | O20: - | P20: - | Q20: - | R20: EVENTOUT | S20: SWCLK debugger, jangan diubah
A21: Port A | B21: PA15 | C21: JTDI | D21: TIM2_CH1 / TIM2_ETR | E21: - | F21: - | G21: - | H21: SPI1_NSS | I21: SPI3_NSS / I2S3_WS | J21: - | K21: - | L21: - | M21: - | N21: - | O21: - | P21: - | Q21: - | R21: EVENTOUT | S21: JTDI (bebas kalau pakai SWD saja)
A22: Port B | B22: PB0 | C22: - | D22: TIM1_CH2N | E22: TIM3_CH3 | F22: TIM8_CH2N | G22: - | H22: - | I22: - | J22: - | K22: - | L22: - | M22: OTG_HS_ULPI_D1 | N22: ETH_MII_RXD2 | O22: - | P22: - | Q22: - | R22: EVENTOUT
A23: Port B | B23: PB1 | C23: - | D23: TIM1_CH3N | E23: TIM3_CH4 | F23: TIM8_CH3N | G23: - | H23: - | I23: - | J23: - | K23: - | L23: - | M23: OTG_HS_ULPI_D2 | N23: ETH_MII_RXD3 | O23: - | P23: - | Q23: - | R23: EVENTOUT
A24: Port B | B24: PB2 | C24: - | D24: - | E24: - | F24: - | G24: - | H24: - | I24: - | J24: - | K24: - | L24: - | M24: - | N24: - | O24: - | P24: - | Q24: - | R24: EVENTOUT | S24: Juga pin BOOT1
A25: Port B | B25: PB3 | C25: JTDO / TRACESWO | D25: TIM2_CH2 | E25: - | F25: - | G25: - | H25: SPI1_SCK | I25: SPI3_SCK / I2S3_CK | J25: - | K25: - | L25: - | M25: - | N25: - | O25: - | P25: - | Q25: - | R25: EVENTOUT | S25: JTDO/SWO (bebas kalau pakai SWD saja)
A26: Port B | B26: PB4 | C26: NJTRST | D26: - | E26: TIM3_CH1 | F26: - | G26: - | H26: SPI1_MISO | I26: SPI3_MISO | J26: I2S3ext_SD | K26: - | L26: - | M26: - | N26: - | O26: - | P26: - | Q26: - | R26: EVENTOUT | S26: NJTRST (bebas kalau pakai SWD saja)
A27: Port B | B27: PB5 | C27: - | D27: - | E27: TIM3_CH2 | F27: - | G27: I2C1_SMBA | H27: SPI1_MOSI | I27: SPI3_MOSI / I2S3_SD | J27: - | K27: - | L27: CAN2_RX | M27: OTG_HS_ULPI_D7 | N27: ETH_PPS_OUT | O27: - | P27: DCMI_D10 | Q27: - | R27: EVENTOUT
A28: Port B | B28: PB6 | C28: - | D28: - | E28: TIM4_CH1 | F28: - | G28: I2C1_SCL | H28: - | I28: - | J28: USART1_TX | K28: - | L28: CAN2_TX | M28: - | N28: - | O28: - | P28: DCMI_D5 | Q28: - | R28: EVENTOUT
A29: Port B | B29: PB7 | C29: - | D29: - | E29: TIM4_CH2 | F29: - | G29: I2C1_SDA | H29: - | I29: - | J29: USART1_RX | K29: - | L29: - | M29: - | N29: - | O29: FSMC_NL | P29: DCMI_VSYNC | Q29: - | R29: EVENTOUT
A30: Port B | B30: PB8 | C30: - | D30: - | E30: TIM4_CH3 | F30: TIM10_CH1 | G30: I2C1_SCL | H30: - | I30: - | J30: - | K30: - | L30: CAN1_RX | M30: - | N30: ETH_MII_TXD3 | O30: SDIO_D4 | P30: DCMI_D6 | Q30: - | R30: EVENTOUT
A31: Port B | B31: PB9 | C31: - | D31: - | E31: TIM4_CH4 | F31: TIM11_CH1 | G31: I2C1_SDA | H31: SPI2_NSS / I2S2_WS | I31: - | J31: - | K31: - | L31: CAN1_TX | M31: - | N31: - | O31: SDIO_D5 | P31: DCMI_D7 | Q31: - | R31: EVENTOUT
A32: Port B | B32: PB10 | C32: - | D32: TIM2_CH3 | E32: - | F32: - | G32: I2C2_SCL | H32: SPI2_SCK / I2S2_CK | I32: - | J32: USART3_TX | K32: - | L32: - | M32: OTG_HS_ULPI_D3 | N32: ETH_MII_RX_ER | O32: - | P32: - | Q32: - | R32: EVENTOUT
A33: Port B | B33: PB11 | C33: - | D33: TIM2_CH4 | E33: - | F33: - | G33: I2C2_SDA | H33: - | I33: - | J33: USART3_RX | K33: - | L33: - | M33: OTG_HS_ULPI_D4 | N33: ETH_MII_TX_ENETH_RMII_TX_EN | O33: - | P33: - | Q33: - | R33: EVENTOUT
A34: Port B | B34: PB12 | C34: - | D34: TIM1_BKIN | E34: - | F34: - | G34: I2C2_SMBA | H34: SPI2_NSS / I2S2_WS | I34: - | J34: USART3_CK | K34: - | L34: CAN2_RX | M34: OTG_HS_ULPI_D5 | N34: ETH_MII_TXD0 / ETH_RMII_TXD0 | O34: OTG_HS_ID | P34: - | Q34: - | R34: EVENTOUT
A35: Port B | B35: PB13 | C35: - | D35: TIM1_CH1N | E35: - | F35: - | G35: - | H35: SPI2_SCK / I2S2_CK | I35: - | J35: USART3_CTS | K35: - | L35: CAN2_TX | M35: OTG_HS_ULPI_D6 | N35: ETH_MII_TXD1 / ETH_RMII_TXD1 | O35: - | P35: - | Q35: - | R35: EVENTOUT
A36: Port B | B36: PB14 | C36: - | D36: TIM1_CH2N | E36: - | F36: TIM8_CH2N | G36: - | H36: SPI2_MISO | I36: I2S2ext_SD | J36: USART3_RTS | K36: - | L36: TIM12_CH1 | M36: - | N36: - | O36: OTG_HS_DM | P36: - | Q36: - | R36: EVENTOUT
A37: Port B | B37: PB15 | C37: RTC_REFIN | D37: TIM1_CH3N | E37: - | F37: TIM8_CH3N | G37: - | H37: SPI2_MOSI / I2S2_SD | I37: - | J37: - | K37: - | L37: TIM12_CH2 | M37: - | N37: - | O37: OTG_HS_DP | P37: - | Q37: - | R37: EVENTOUT
A38: Port C | B38: PC0 | C38: - | D38: - | E38: - | F38: - | G38: - | H38: - | I38: - | J38: - | K38: - | L38: - | M38: OTG_HS_ULPI_STP | N38: - | O38: - | P38: - | Q38: - | R38: EVENTOUT
... A50: Port C | B50: PC12 | C50: - | D50: - | E50: - | F50: - | G50: - | H50: - | I50: SPI3_MOSI / I2S3_SD | J50: USART3_CK | K50: UART5_TX | L50: - | M50: - | N50: - | O50: SDIO_CK | P50: DCMI_D9 | Q50: - | R50: EVENTOUT
A51: Port C | B51: PC13 | C51: - | D51: - | E51: - | F51: - | G51: - | H51: - | I51: - | J51: - | K51: - | L51: - | M51: - | N51: - | O51: - | P51: - | Q51: - | R51: - | S51: RTC/tamper, arus keluaran terbatas (maks 3 mA)
A52: Port C | B52: PC14 | C52: - | D52: - | E52: - | F52: - | G52: - | H52: - | I52: - | J52: - | K52: - | L52: - | M52: - | N52: - | O52: - | P52: - | Q52: - | R52: - | S52: Pin kristal LSE 32 kHz
...

Sheet Cari Sinyal
A1: Cari Sinyal → Pin
A2: Ketik nama sinyal di filter kolom A (mis. TIM3_CH1, USART2_TX, I2C1_SCL). Kolom "Nilai AF" adalah angka yang ditulis ke AFRL/AFRH.
A4: Sinyal | B4: Peripheral | C4: Pin | D4: Nilai AF | E4: Register AF
A5: CAN1_RX | B5: CAN1 | C5: PA11 | D5: 9 | E5: AFRH
A6: CAN1_RX | B6: CAN1 | C6: PB8 | D6: 9 | E6: AFRH
A7: CAN1_RX | B7: CAN1 | C7: PD0 | D7: 9 | E7: AFRL
A8: CAN1_RX | B8: CAN1 | C8: PI9 | D8: 9 | E8: AFRH
A9: CAN1_TX | B9: CAN1 | C9: PA12 | D9: 9 | E9: AFRH
A10: CAN1_TX | B10: CAN1 | C10: PB9 | D10: 9 | E10: AFRH
A11: CAN1_TX | B11: CAN1 | C11: PD1 | D11: 9 | E11: AFRL
A12: CAN1_TX | B12: CAN1 | C12: PH13 | D12: 9 | E12: AFRH
A13: CAN2_RX | B13: CAN2 | C13: PB5 | D13: 9 | E13: AFRL
A14: CAN2_RX | B14: CAN2 | C14: PB12 | D14: 9 | E14: AFRH
A15: CAN2_TX | B15: CAN2 | C15: PB6 | D15: 9 | E15: AFRL
A16: CAN2_TX | B16: CAN2 | C16: PB13 | D16: 9 | E16: AFRH
... A420: USART6_TX | B420: USART6 | C420: PG14 | D420: 8 | E420: AFRH

Sheet Timer
A1: Ringkasan Timer
A2: Sumber: DS8626 Table 4 (hal. 33-34) dan Table 9. Clock timer = 2x clock bus APB jika prescaler APB ≠ 1. Setelah reset (HSI 16 MHz, tanpa PLL) semua timer berdetak 16 MHz.
A4: Timer | B4: Jenis | C4: Bus | D4: Base | E4: Resolusi | F4: Arah hitung | G4: Jumlah channel | H4: Output komplementer | I4: DMA | J4: Clock interface maks (MHz) | K4: Clock timer maks (MHz) | L4: Enable clock | M4: Pin CH1 | N4: Pin CH2 | O4: Pin CH3 | P4: Pin CH4 | Q4: Pin CHxN | R4: Pin ETR | S4: Pin BKIN
A5: TIM1 | B5: Advanced | C5: APB2 | D5: 0x40010000 | E5: 16-bit | F5: Up/Down/Up-down | G5: 4 | H5: Ya | I5: Ya | J5: 84 | K5: 168 | L5: RCC_APB2ENR bit 0 (TIM1EN) | M5: PA8 (AF1), PE9 (AF1) | N5: PA9 (AF1), PE11 (AF1) | O5: PA10 (AF1), PE13 (AF1) | P5: PA11 (AF1), PE14 (AF1) | Q5: CH1N: PA7 (AF1), PB13 (AF1), PE8 (AF1) | CH2N: PB0 (AF1), PB14 (AF1), PE10 (AF1) | CH3N: PB1 (AF1), PB15 (AF1), PE12 (AF1) | R5: PA12 (AF1), PE7 (AF1) | S5: PA6 (AF1), PB12 (AF1), PE15 (AF1)
A6: TIM8 | B6: Advanced | C6: APB2 | D6: 0x40010400 | E6: 16-bit | F6: Up/Down/Up-down | G6: 4 | H6: Ya | I6: Ya | J6: 84 | K6: 168 | L6: RCC_APB2ENR bit 1 (TIM8EN) | M6: PC6 (AF3), PI5 (AF3) | N6: PC7 (AF3), PI6 (AF3) | O6: PC8 (AF3), PI7 (AF3) | P6: PC9 (AF3), PI2 (AF3) | Q6: CH1N: PA5 (AF3), PA7 (AF3), PH13 (AF3) | CH2N: PB0 (AF3), PB14 (AF3), PH14 (AF3) | CH3N: PB1 (AF3), PB15 (AF3), PH15 (AF3) | R6: PA0 (AF3), PI3 (AF3) | S6: PA6 (AF3), PI4 (AF3)
A7: TIM2 | B7: General purpose | C7: APB1 | D7: 0x40000000 | E7: 32-bit | F7: Up/Down/Up-down | G7: 4 | H7: Tidak | I7: Ya | J7: 42 | K7: 84 | L7: RCC_APB1ENR bit 0 (TIM2EN) | M7: PA0 (AF1), PA5 (AF1), PA15 (AF1) | N7: PA1 (AF1), PB3 (AF1) | O7: PA2 (AF1), PB10 (AF1) | P7: PA3 (AF1), PB11 (AF1) | Q7: - | R7: PA0 (AF1), PA5 (AF1), PA15 (AF1) | S7: -
A8: TIM3 | B8: General purpose | C8: APB1 | D8: 0x40000400 | E8: 16-bit | F8: Up/Down/Up-down | G8: 4 | H8: Tidak | I8: Ya | J8: 42 | K8: 84 | L8: RCC_APB1ENR bit 1 (TIM3EN) | M8: PA6 (AF2), PB4 (AF2), PC6 (AF2) | N8: PA7 (AF2), PB5 (AF2), PC7 (AF2) | O8: PB0 (AF2), PC8 (AF2) | P8: PB1 (AF2), PC9 (AF2) | Q8: - | R8: PD2 (AF2) | S8: -
A9: TIM4 | B9: General purpose | C9: APB1 | D9: 0x40000800 | E9: 16-bit | F9: Up/Down/Up-down | G9: 4 | H9: Tidak | I9: Ya | J9: 42 | K9: 84 | L9: RCC_APB1ENR bit 2 (TIM4EN) | M9: PB6 (AF2), PD12 (AF2) | N9: PB7 (AF2), PD13 (AF2) | O9: PB8 (AF2), PD14 (AF2) | P9: PB9 (AF2), PD15 (AF2) | Q9: - | R9: PE0 (AF2) | S9: -
A10: TIM5 | B10: General purpose | C10: APB1 | D10: 0x40000C00 | E10: 32-bit | F10: Up/Down/Up-down | G10: 4 | H10: Tidak | I10: Ya | J10: 42 | K10: 84 | L10: RCC_APB1ENR bit 3 (TIM5EN) | M10: PA0 (AF2), PH10 (AF2) | N10: PA1 (AF2), PH11 (AF2) | O10: PA2 (AF2), PH12 (AF2) | P10: PA3 (AF2), PI0 (AF2) | Q10: - | R10: - | S10: -
A11: TIM9 | B11: General purpose | C11: APB2 | D11: 0x40014000 | E11: 16-bit | F11: Up | G11: 2 | H11: Tidak | I11: Tidak | J11: 84 | K11: 168 | L11: RCC_APB2ENR bit 16 (TIM9EN) | M11: PA2 (AF3), PE5 (AF3) | N11: PA3 (AF3), PE6 (AF3) | O11: - | P11: - | Q11: - | R11: - | S11: -
A12: TIM10 | B12: General purpose | C12: APB2 | D12: 0x40014400 | E12: 16-bit | F12: Up | G12: 1 | H12: Tidak | I12: Tidak | J12: 84 | K12: 168 | L12: RCC_APB2ENR bit 17 (TIM10EN) | M12: PB8 (AF3), PF6 (AF3) | N12: - | O12: - | P12: - | Q12: - | R12: - | S12: -
A13: TIM11 | B13: General purpose | C13: APB2 | D13: 0x40014800 | E13: 16-bit | F13: Up | G13: 1 | H13: Tidak | I13: Tidak | J13: 84 | K13: 168 | L13: RCC_APB2ENR bit 18 (TIM11EN) | M13: PB9 (AF3), PF7 (AF3) | N13: - | O13: - | P13: - | Q13: - | R13: - | S13: -
A14: TIM12 | B14: General purpose | C14: APB1 | D14: 0x40001800 | E14: 16-bit | F14: Up | G14: 2 | H14: Tidak | I14: Tidak | J14: 42 | K14: 84 | L14: RCC_APB1ENR bit 6 (TIM12EN) | M14: PB14 (AF9), PH6 (AF9) | N14: PB15 (AF9), PH9 (AF9) | O14: - | P14: - | Q14: - | R14: - | S14: -
A15: TIM13 | B15: General purpose | C15: APB1 | D15: 0x40001C00 | E15: 16-bit | F15: Up | G15: 1 | H15: Tidak | I15: Tidak | J15: 42 | K15: 84 | L15: RCC_APB1ENR bit 7 (TIM13EN) | M15: PA6 (AF9), PF8 (AF9) | N15: - | O15: - | P15: - | Q15: - | R15: - | S15: -
A16: TIM14 | B16: General purpose | C16: APB1 | D16: 0x40002000 | E16: 16-bit | F16: Up | G16: 1 | H16: Tidak | I16: Tidak | J16: 42 | K16: 84 | L16: RCC_APB1ENR bit 8 (TIM14EN) | M16: PA7 (AF9), PF9 (AF9) | N16: - | O16: - | P16: - | Q16: - | R16: - | S16: -
... A18: TIM7 | B18: Basic | C18: APB1 | D18: 0x40001400 | E18: 16-bit | F18: Up | G18: 0 | H18: Tidak | I18: Ya | J18: 42 | K18: 84 | L18: RCC_APB1ENR bit 5 (TIM7EN) | M18: - | N18: - | O18: - | P18: - | Q18: - | R18: - | S18: -
A20: Rumus PWM
A21: Frekuensi PWM = clock timer / ((PSC + 1) × (ARR + 1)) Duty cycle = CCRx / (ARR + 1)
A23: Kalkulator PWM (isi sel kuning)
A24: Clock timer (Hz) | B24: 16000000 | C24: Contoh: HSI 16 MHz setelah reset
A25: PSC | B25: 15
A26: ARR | B26: 999
A27: CCR | B27: 250
A28: Frekuensi PWM (Hz) | B28: =B24/((B25+1)*(B26+1)) -> 1000
A29: Duty cycle | B29: =B27/(B26+1) -> 0.25
A30: Periode (ms) | B30: =1000/B28 -> 1

Sheet Kalkulator Alamat
A1: Kalkulator Alamat Register
A2: Isi dua sel kuning. Nama peripheral harus sama persis dengan kolom Peripheral (mis. GPIOD, TIM3, USART2, RCC, SysTick).
A4: Peripheral | B4: GPIOD
A5: Register | B5: ODR
A7: Kelompok register | B7: =INDEX(Peripheral!$E$5:$E$72,MATCH(B4,Peripheral!$B$5:$B$72,0)) -> GPIO
A8: Base address | B8: =INDEX(Peripheral!$C$5:$C$72,MATCH(B4,Peripheral!$B$5:$B$72,0)) -> 0x40020C00
A9: Offset | B9: =INDEX(Register!$C$5:$C$118,MATCH(B7&"|"&B5,Register!$H$5:$H$118,0)) -> 0x14
A10: ALAMAT REGISTER | B10: =IFERROR("0x"&DEC2HEX(HEX2DEC(SUBSTITUTE(B8,"0x",""))+HEX2DEC(SUBSTITUTE(B9,"0x","")),8),"Tidak ditemukan: cek ejaan") -> 0x40020C14
A11: Fungsi | B11: =IFERROR(INDEX(Register!$F$5:$F$118,MATCH(B7&"|"&B5,Register!$H$5:$H$118,0)),"-") -> Menulis level output. 1 bit per pin
A12: Bit penting | B12: =IFERROR(INDEX(Register!$G$5:$G$118,MATCH(B7&"|"&B5,Register!$H$5:$H$118,0)),"-") -> Read-modify-write: hati-hati kalau diubah juga oleh interrupt
A13: Baris untuk kode C | B13: =IFERROR("#define "&B4&"_"&B5&" (*(volatile uint32_t *)"&B10&"UL)","-") -> #define GPIOD_ODR (*(volatile uint32_t *)0x40020C14UL)
